Workbook

Sheet MASTER
A1: MASTER DATA & ASUMSI — isi sel kuning terlebih dahulu
B4: Nama Perusahaan | C4: PT GEMBIRA ANGGUN SETIA | E4: Muncul di judul laporan.
B5: Periode Pencatatan | C5: Agustus 2026 | E5: Format: Bulan Tahun.
B6: Harga BBM (Rp/Liter) | C6: 0
B7: Stok Awal BBM (Liter) | C7: 0
B8: DAFTAR ALAT / UNIT
B9: No Lambung | C9: Tipe Alat | D9: COST / ALAT | E9: Vendor | F9: Kapasitas Tangki (Ltr) | G9: Status
B10: BOMAG | C10: VIBRO | D10: 275000 | E10: PT GAS | F10: 400 | G10: Aktif
B11: EXCA GAS 001 | C11: PC 200 | D11: 275000 | E11: PT GAS | F11: 400 | G11: Aktif
B12: GAS 006 | C12: PC 300 | D12: 450000 | E12: PT GAS | F12: 400 | G12: Aktif
B13: GRADER | C13: LONG ARM | D13: 275000 | E13: PT GAS | F13: 400 | G13: Aktif
B14: KOBELCO LONG ARM | C14: GRADER | D14: 450000 | E14: PT GAS | F14: 400 | G14: Aktif
B15: KOMATSU | C15: LOADER | D15: 450000 | E15: PT GAS | F15: 400 | G15: Aktif
B16: LODER | E16: PT GAS | F16: 400 | G16: Aktif
B17: SDLG | E17: PT GAS | F17: 400 | G17: Aktif
B18: VIBRO/BOMAG | E18: PT GAS | F18: 400 | G18: Aktif
B19: XCMG | E19: PT GAS | F19: 400 | G19: Aktif
B20: EXCA SDLG PC 200 | E20: PT GAS | F20: 400 | G20: Aktif
B21: EXCA XCMG PC 200 | E21: PT GAS | F21: 400 | G21: Aktif
B22: EXCAVATOR XCMG PC 200 | E22: PT GAS | F22: 400 | G22: Aktif
B23: GREADER | E23: PT GAS | F23: 400 | G23: Aktif
B24: GREDER
B25: KOBELCO LONG ARM
B26: LOADER
B27: LODER
B28: PC 200
B29: SDLG
B30: VIBRO
B31: VIBRO/BOMAG
B32: XCMG
B41: Catatan: baris di atas adalah CONTOH. Ganti dengan daftar alat sebenarnya. Penulisan No Lambung di sheet HM dan BBM harus persis sama dengan daftar ini agar rekap otomatis akurat.

Sheet BBM
A1: PENCATATAN BAHAN BAKAR MINYAK (BBM) / SOLAR
A2: BULAN | B2: TANGGAL | C2: NAMA OPT / DRIVER | D2: ALAT / NO LAMBUNG | E2: DESKRIPSI AKTIVITAS | F2: LOKASI KEGIATAN | G2: BBM / LTR (KELUAR) | H2: BBM MASUK (LTR) | I2: SISA STOK (LTR) | J2: HARGA / LTR (RP) | K2: NILAI BBM KELUAR (RP) | L2: NILAI BBM MASUK (RP) | M2: KETERANGAN
A3: =IF(B3="","",TEXT(B3,"MMMM YYYY")) -> May 2026 | B3: 46154 | C3: ERWIN | D3: 01 HYUNDAI | E3: PERBAIKI JALAN | F3: PT CMM | G3: 50 | H3: 10000 | I3: =IF(B3="","",MASTER!$C$7+N(H3)-N(G3)) -> 9950 | J3: 19000 | K3: =IF(OR(B3="",J3=""),"",N(G3)*J3) -> 950000 | L3: =IF(OR(B3="",H3="",J3=""),"",N(H3)*J3) -> 190000000
A4: =IF(B4="","",TEXT(B4,"MMMM YYYY")) -> May 2026 | B4: 46154 | C4: PIKRAM | D4: 010 HYUNDAI | E4: PERBAIKI JALAN | F4: PT CMM | G4: 50 | I4: =IF(B4="","",IF(I3="",MASTER!$C$7,I3)+N(H4)-N(G4)) -> 9900 | J4: 19000 | K4: =IF(OR(B4="",J4=""),"",N(G4)*J4) -> 950000 | L4: =IF(OR(B4="",H4="",J4=""),"",N(H4)*J4)
A5: =IF(B5="","",TEXT(B5,"MMMM YYYY")) -> May 2026 | B5: 46154 | C5: ANTO | D5: LIUGONG | E5: PERBAIKI JALAN | F5: PT CMM | G5: 100 | I5: =IF(B5="","",IF(I4="",MASTER!$C$7,I4)+N(H5)-N(G5)) -> 9800 | J5: 19000 | K5: =IF(OR(B5="",J5=""),"",N(G5)*J5) -> 1900000 | L5: =IF(OR(B5="",H5="",J5=""),"",N(H5)*J5)
A6: =IF(B6="","",TEXT(B6,"MMMM YYYY")) -> May 2026 | B6: 46154 | C6: SANDRI | D6: 02 HYUNDAI | E6: PERBAIKI JALAN | F6: PT CMM | G6: 50 | I6: =IF(B6="","",IF(I5="",MASTER!$C$7,I5)+N(H6)-N(G6)) -> 9750 | J6: 19000 | K6: =IF(OR(B6="",J6=""),"",N(G6)*J6) -> 950000 | L6: =IF(OR(B6="",H6="",J6=""),"",N(H6)*J6)
A7: =IF(B7="","",TEXT(B7,"MMMM YYYY")) -> May 2026 | B7: 46154 | C7: LUKAS | D7: 025 DOOSAN | E7: PERBAIKI JALAN | F7: PT CMM | G7: 150 | I7: =IF(B7="","",IF(I6="",MASTER!$C$7,I6)+N(H7)-N(G7)) -> 9600 | J7: 19000 | K7: =IF(OR(B7="",J7=""),"",N(G7)*J7) -> 2850000 | L7: =IF(OR(B7="",H7="",J7=""),"",N(H7)*J7)
A8: =IF(B8="","",TEXT(B8,"MMMM YYYY")) -> May 2026 | B8: 46155 | C8: NUNUNG | D8: LOADER | E8: MAINTANANCE | F8: CV MKM | G8: 160 | I8: =IF(B8="","",IF(I7="",MASTER!$C$7,I7)+N(H8)-N(G8)) -> 9440 | J8: 19000 | K8: =IF(OR(B8="",J8=""),"",N(G8)*J8) -> 3040000 | L8: =IF(OR(B8="",H8="",J8=""),"",N(H8)*J8)
A9: =IF(B9="","",TEXT(B9,"MMMM YYYY")) -> May 2026 | B9: 46155 | C9: ARDI | D9: 07 DT HINO | E9: MUAT KUARSA | F9: PT CMM | G9: 100 | I9: =IF(B9="","",IF(I8="",MASTER!$C$7,I8)+N(H9)-N(G9)) -> 9340 | J9: 19000 | K9: =IF(OR(B9="",J9=""),"",N(G9)*J9) -> 1900000 | L9: =IF(OR(B9="",H9="",J9=""),"",N(H9)*J9)
A10: =IF(B10="","",TEXT(B10,"MMMM YYYY")) -> May 2026 | B10: 46155 | C10: ANCA | D10: DEVELON 300 | E10: PERBAIKI JALAN | F10: PT CMM | G10: 200 | I10: =IF(B10="","",IF(I9="",MASTER!$C$7,I9)+N(H10)-N(G10)) -> 9140 | J10: 19000 | K10: =IF(OR(B10="",J10=""),"",N(G10)*J10) -> 3800000 | L10: =IF(OR(B10="",H10="",J10=""),"",N(H10)*J10)
A11: =IF(B11="","",TEXT(B11,"MMMM YYYY")) -> May 2026 | B11: 46155 | C11: LUKAS | D11: HYUNDAI 300 | E11: PERBAIKI JALAN | F11: PT CMM | G11: 200 | I11: =IF(B11="","",IF(I10="",MASTER!$C$7,I10)+N(H11)-N(G11)) -> 8940 | J11: 19000 | K11: =IF(OR(B11="",J11=""),"",N(G11)*J11) -> 3800000 | L11: =IF(OR(B11="",H11="",J11=""),"",N(H11)*J11)
A12: =IF(B12="","",TEXT(B12,"MMMM YYYY")) -> May 2026 | B12: 46155 | C12: KADEK | D12: 05 DT HINO | E12: MUAT KUARSA | F12: PT CMM | G12: 100 | I12: =IF(B12="","",IF(I11="",MASTER!$C$7,I11)+N(H12)-N(G12)) -> 8840 | J12: 19000 | K12: =IF(OR(B12="",J12=""),"",N(G12)*J12) -> 1900000 | L12: =IF(OR(B12="",H12="",J12=""),"",N(H12)*J12)
A13: =IF(B13="","",TEXT(B13,"MMMM YYYY")) -> May 2026 | B13: 46155 | C13: DENDI | D13: 06 DT HINO | E13: MUAT KUARSA | F13: PT CMM | G13: 50 | I13: =IF(B13="","",IF(I12="",MASTER!$C$7,I12)+N(H13)-N(G13)) -> 8790 | J13: 19000 | K13: =IF(OR(B13="",J13=""),"",N(G13)*J13) -> 950000 | L13: =IF(OR(B13="",H13="",J13=""),"",N(H13)*J13)
A14: =IF(B14="","",TEXT(B14,"MMMM YYYY")) -> May 2026 | B14: 46155 | C14: FADLI | D14: ZOOMLION 05 | E14: PERBAIKI JALAN | F14: PT CMM | G14: 200 | I14: =IF(B14="","",IF(I13="",MASTER!$C$7,I13)+N(H14)-N(G14)) -> 8590 | J14: 19000 | K14: =IF(OR(B14="",J14=""),"",N(G14)*J14) -> 3800000 | L14: =IF(OR(B14="",H14="",J14=""),"",N(H14)*J14)
A15: =IF(B15="","",TEXT(B15,"MMMM YYYY")) -> May 2026 | B15: 46155 | C15: MADE SUDANA | D15: 04 DT HINO | E15: MUAT KUARSA | F15: PT CMM | G15: 100 | I15: =IF(B15="","",IF(I14="",MASTER!$C$7,I14)+N(H15)-N(G15)) -> 8490 | J15: 19000 | K15: =IF(OR(B15="",J15=""),"",N(G15)*J15) -> 1900000 | L15: =IF(OR(B15="",H15="",J15=""),"",N(H15)*J15)
... A61: =IF(B61="","",TEXT(B61,"MMMM YYYY")) -> May 2026 | B61: 46163 | C61: LUKAS | D61: 25 DOOSAN | E61: LOADING ORE | F61: PT CMM | G61: 270 | I61: =IF(B61="","",IF(I60="",MASTER!$C$7,I60)+N(H61)-N(G61)) -> 3243 | J61: 19000 | K61: =IF(OR(B61="",J61=""),"",N(G61)*J61) -> 5130000 | L61: =IF(OR(B61="",H61="",J61=""),"",N(H61)*J61)
A62: =IF(B62="","",TEXT(B62,"MMMM YYYY")) -> May 2026 | B62: 46164 | C62: DARMIN | D62: DT SRI 49 | E62: MUAT ORE | F62: PT SRI | G62: 50 | H62: 10000 | I62: =IF(B62="","",IF(I61="",MASTER!$C$7,I61)+N(H62)-N(G62)) -> 13193 | J62: 19000 | K62: =IF(OR(B62="",J62=""),"",N(G62)*J62) -> 950000 | L62: =IF(OR(B62="",H62="",J62=""),"",N(H62)*J62) -> 190000000
A63: =IF(B63="","",TEXT(B63,"MMMM YYYY")) -> May 2026 | B63: 46164 | C63: IKAL | D63: DT SRI 58 | E63: MUAT ORE | F63: PT SRI | G63: 50 | I63: =IF(B63="","",IF(I62="",MASTER!$C$7,I62)+N(H63)-N(G63)) -> 13143 | J63: 19000 | K63: =IF(OR(B63="",J63=""),"",N(G63)*J63) -> 950000 | L63: =IF(OR(B63="",H63="",J63=""),"",N(H63)*J63)
A64: =IF(B64="","",TEXT(B64,"MMMM YYYY")) -> May 2026 | B64: 46164 | C64: HASIM | D64: DT SRI 50 | E64: MUAT ORE | F64: PT SRI | G64: 50 | I64: =IF(B64="","",IF(I63="",MASTER!$C$7,I63)+N(H64)-N(G64)) -> 13093 | J64: 19000 | K64: =IF(OR(B64="",J64=""),"",N(G64)*J64) -> 950000 | L64: =IF(OR(B64="",H64="",J64=""),"",N(H64)*J64)
A65: =IF(B65="","",TEXT(B65,"MMMM YYYY")) -> May 2026 | B65: 46164 | C65: RIRIN | D65: DT SRI 52 | E65: MUAT ORE | F65: PT SRI | G65: 50 | I65: =IF(B65="","",IF(I64="",MASTER!$C$7,I64)+N(H65)-N(G65)) -> 13043 | J65: 19000 | K65: =IF(OR(B65="",J65=""),"",N(G65)*J65) -> 950000 | L65: =IF(OR(B65="",H65="",J65=""),"",N(H65)*J65)
A66: =IF(B66="","",TEXT(B66,"MMMM YYYY")) -> May 2026 | B66: 46164 | C66: MUH YUSRIL | D66: DT SRI 57 | E66: MUAT ORE | F66: PT SRI | G66: 50 | I66: =IF(B66="","",IF(I65="",MASTER!$C$7,I65)+N(H66)-N(G66)) -> 12993 | J66: 19000 | K66: =IF(OR(B66="",J66=""),"",N(G66)*J66) -> 950000 | L66: =IF(OR(B66="",H66="",J66=""),"",N(H66)*J66)
A67: =IF(B67="","",TEXT(B67,"MMMM YYYY")) -> May 2026 | B67: 46164 | C67: AKSAN | D67: DT SRI 45 | E67: MUAT ORE | F67: PT SRI | G67: 50 | I67: =IF(B67="","",IF(I66="",MASTER!$C$7,I66)+N(H67)-N(G67)) -> 12943 | J67: 19000 | K67: =IF(OR(B67="",J67=""),"",N(G67)*J67) -> 950000 | L67: =IF(OR(B67="",H67="",J67=""),"",N(H67)*J67)
A68: =IF(B68="","",TEXT(B68,"MMMM YYYY")) -> May 2026 | B68: 46164 | C68: KADEK | D68: 05 DT HINO | E68: MUAT ORE | F68: PT CMM | G68: 125 | I68: =IF(B68="","",IF(I67="",MASTER!$C$7,I67)+N(H68)-N(G68)) -> 12818 | J68: 19000 | K68: =IF(OR(B68="",J68=""),"",N(G68)*J68) -> 2375000 | L68: =IF(OR(B68="",H68="",J68=""),"",N(H68)*J68)
A69: =IF(B69="","",TEXT(B69,"MMMM YYYY")) -> May 2026 | B69: 46164 | C69: ARDI | D69: 07 DT HINO | E69: MUAT ORE | F69: PT CMM | G69: 95 | I69: =IF(B69="","",IF(I68="",MASTER!$C$7,I68)+N(H69)-N(G69)) -> 12723 | J69: 19000 | K69: =IF(OR(B69="",J69=""),"",N(G69)*J69) -> 1805000 | L69: =IF(OR(B69="",H69="",J69=""),"",N(H69)*J69)
A70: =IF(B70="","",TEXT(B70,"MMMM YYYY")) -> May 2026 | B70: 46164 | C70: DENDI | D70: 06 DT HINO | E70: MUAT ORE | F70: PT CMM | G70: 110 | I70: =IF(B70="","",IF(I69="",MASTER!$C$7,I69)+N(H70)-N(G70)) -> 12613 | J70: 19000 | K70: =IF(OR(B70="",J70=""),"",N(G70)*J70) -> 2090000 | L70: =IF(OR(B70="",H70="",J70=""),"",N(H70)*J70)
A71: =IF(B71="","",TEXT(B71,"MMMM YYYY")) -> May 2026 | B71: 46164 | C71: MADE SUDANA | D71: 02 DT MERCI | E71: MUAT ORE | F71: PT CMM | G71: 100 | I71: =IF(B71="","",IF(I70="",MASTER!$C$7,I70)+N(H71)-N(G71)) -> 12513 | J71: 19000 | K71: =IF(OR(B71="",J71=""),"",N(G71)*J71) -> 1900000 | L71: =IF(OR(B71="",H71="",J71=""),"",N(H71)*J71)
A72: =IF(B72="","",TEXT(B72,"MMMM YYYY")) -> May 2026 | B72: 46164 | C72: ADI | D72: LV MEKANIK | E72: PERBAIKI ALAT | F72: PT CMM | G72: 70 | I72: =IF(B72="","",IF(I71="",MASTER!$C$7,I71)+N(H72)-N(G72)) -> 12443 | J72: 19000 | K72: =IF(OR(B72="",J72=""),"",N(G72)*J72) -> 1330000 | L72: =IF(OR(B72="",H72="",J72=""),"",N(H72)*J72)
A73: =IF(B73="","",TEXT(B73,"MMMM YYYY")) -> May 2026 | B73: 46164 | C73: ADRIANTO | D73: 04 DT HINO | E73: MUAT ORE | F73: PT CMM | G73: 85 | I73: =IF(B73="","",IF(I72="",MASTER!$C$7,I72)+N(H73)-N(G73)) -> 12358 | J73: 19000 | K73: =IF(OR(B73="",J73=""),"",N(G73)*J73) -> 1615000 | L73: =IF(OR(B73="",H73="",J73=""),"",N(H73)*J73)
A74: =IF(B74="","",TEXT(B74,"MMMM YYYY")) -> May 2026 | B74: 46164 | C74: ANCA | D74: PC 300 DEVELON | E74: LOADING ORE | F74: PT CMM | G74: 245 | I74: =IF(B74="","",IF(I73="",MASTER!$C$7,I73)+N(H74)-N(G74)) -> 12113 | J74: 19000 | K74: =IF(OR(B74="",J74=""),"",N(G74)*J74) -> 4655000 | L74: =IF(OR(B74="",H74="",J74=""),"",N(H74)*J74)
... A138: =IF(B138="","",TEXT(B138,"MMMM YYYY")) -> May 2026 | B138: 46172 | C138: DARMIN | D138: DT FUSO 49 | E138: MUAT ORE | F138: PT SRI | G138: 50 | I138: =IF(B138="","",IF(I137="",MASTER!$C$7,I137)+N(H138)-N(G138)) -> 4643 | J138: 19000 | K138: =IF(OR(B138="",J138=""),"",N(G138)*J138) -> 950000 | L138: =IF(OR(B138="",H138="",J138=""),"",N(H138)*J138)
A139: =IF(B139="","",TEXT(B139,"MMMM YYYY")) -> May 2026 | B139: 46173 | C139: NURHASIM | D139: DT FUSO 50 | E139: MUAT ORE | F139: PT SRI | G139: 50 | H139: 5000 | I139: =IF(B139="","",IF(I138="",MASTER!$C$7,I138)+N(H139)-N(G139)) -> 9593 | J139: 19000 | K139: =IF(OR(B139="",J139=""),"",N(G139)*J139) -> 950000 | L139: =IF(OR(B139="",H139="",J139=""),"",N(H139)*J139) -> 95000000
A140: =IF(B140="","",TEXT(B140,"MMMM YYYY")) -> May 2026 | B140: 46173 | C140: RIAN | D140: DT FUSO 59 | E140: MUAT ORE | F140: PT SRI | G140: 50 | I140: =IF(B140="","",IF(I139="",MASTER!$C$7,I139)+N(H140)-N(G140)) -> 9543 | J140: 19000 | K140: =IF(OR(B140="",J140=""),"",N(G140)*J140) -> 950000 | L140: =IF(OR(B140="",H140="",J140=""),"",N(H140)*J140)
A141: =IF(B141="","",TEXT(B141,"MMMM YYYY")) -> May 2026 | B141: 46173 | C141: DARMIN | D141: DT FUSO 49 | E141: MUAT ORE | F141: PT SRI | G141: 50 | I141: =IF(B141="","",IF(I140="",MASTER!$C$7,I140)+N(H141)-N(G141)) -> 9493 | J141: 19000 | K141: =IF(OR(B141="",J141=""),"",N(G141)*J141) -> 950000 | L141: =IF(OR(B141="",H141="",J141=""),"",N(H141)*J141)
A142: =IF(B142="","",TEXT(B142,"MMMM YYYY")) -> May 2026 | B142: 46173 | C142: MUH YUSRIL | D142: DT FUSO 44 | E142: MUAT ORE | F142: PT SRI | G142: 50 | I142: =IF(B142="","",IF(I141="",MASTER!$C$7,I141)+N(H142)-N(G142)) -> 9443 | J142: 19000 | K142: =IF(OR(B142="",J142=""),"",N(G142)*J142) -> 950000 | L142: =IF(OR(B142="",H142="",J142=""),"",N(H142)*J142)
A143: =IF(B143="","",TEXT(B143,"MMMM YYYY")) -> May 2026 | B143: 46173 | C143: AKSAN | D143: DT FUSO 45 | E143: MUAT ORE | F143: PT SRI | G143: 50 | I143: =IF(B143="","",IF(I142="",MASTER!$C$7,I142)+N(H143)-N(G143)) -> 9393 | J143: 19000 | K143: =IF(OR(B143="",J143=""),"",N(G143)*J143) -> 950000 | L143: =IF(OR(B143="",H143="",J143=""),"",N(H143)*J143)
A144: =IF(B144="","",TEXT(B144,"MMMM YYYY")) -> May 2026 | B144: 46173 | C144: KESRAN | D144: DT FUSO 46 | E144: MUAT ORE | F144: PT SRI | G144: 50 | I144: =IF(B144="","",IF(I143="",MASTER!$C$7,I143)+N(H144)-N(G144)) -> 9343 | J144: 19000 | K144: =IF(OR(B144="",J144=""),"",N(G144)*J144) -> 950000 | L144: =IF(OR(B144="",H144="",J144=""),"",N(H144)*J144)
A145: =IF(B145="","",TEXT(B145,"MMMM YYYY")) -> May 2026 | B145: 46173 | C145: MUH YUSRIL | D145: DT FUSO 43 | E145: MUAT ORE | F145: PT SRI | G145: 50 | I145: =IF(B145="","",IF(I144="",MASTER!$C$7,I144)+N(H145)-N(G145)) -> 9293 | J145: 19000 | K145: =IF(OR(B145="",J145=""),"",N(G145)*J145) -> 950000 | L145: =IF(OR(B145="",H145="",J145=""),"",N(H145)*J145)
A146: =IF(B146="","",TEXT(B146,"MMMM YYYY")) -> May 2026 | B146: 46173 | C146: IKAL | D146: DT FUSO 58 | E146: MUAT ORE | F146: PT SRI | G146: 50 | I146: =IF(B146="","",IF(I145="",MASTER!$C$7,I145)+N(H146)-N(G146)) -> 9243 | J146: 19000 | K146: =IF(OR(B146="",J146=""),"",N(G146)*J146) -> 950000 | L146: =IF(OR(B146="",H146="",J146=""),"",N(H146)*J146)
A147: =IF(B147="","",TEXT(B147,"MMMM YYYY")) -> May 2026 | B147: 46173 | C147: TEDDY | D147: DT FUSO 42 | E147: MUAT ORE | F147: PT SRI | G147: 50 | I147: =IF(B147="","",IF(I146="",MASTER!$C$7,I146)+N(H147)-N(G147)) -> 9193 | J147: 19000 | K147: =IF(OR(B147="",J147=""),"",N(G147)*J147) -> 950000 | L147: =IF(OR(B147="",H147="",J147=""),"",N(H147)*J147)
A148: =IF(B148="","",TEXT(B148,"MMMM YYYY")) -> May 2026 | B148: 46173 | C148: SAMSUL | D148: DT HOWO 07 | E148: MUAT ORE | F148: RISAL BAS NAPAL | G148: 100 | I148: =IF(B148="","",IF(I147="",MASTER!$C$7,I147)+N(H148)-N(G148)) -> 9093 | J148: 19000 | K148: =IF(OR(B148="",J148=""),"",N(G148)*J148) -> 1900000 | L148: =IF(OR(B148="",H148="",J148=""),"",N(H148)*J148)
...

Sheet LAPORAN HM + BBM
B1: NO | C1: TANGGAL | D1: NAMA OPERATOR | E1: NO LAMBUNG ( ALAT ) | F1: JUMLAH BBM | G1: HM AWAL | H1: HM AKHIR | I1: TOTAL | J1: KETERANGAN
B2: 1 | C2: 46262 | D2: RONAL | E2: LOADER | F2: 150 | G2: 17455 | H2: 17460 | I2: =H2-G2 -> 5 | J2: ISI TIMBUNAN DI STP
B3: 2 | C3: 46263 | D3: RONAL | E3: LOADER | F3: 105 | G3: 17460 | H3: 17464.7 | I3: =H3-G3 -> 4.7 | J3: ISI BATU DT DI STP
B4: 3 | C4: 46264 | D4: RANTE | E4: SDLG 007 | F4: 0 | G4: 744.7 | H4: 751.9 | I4: =H4-G4 -> 7.2 | J4: MAINTENANCE JALAN
B5: 4 | C5: 46264 | D5: HARDI | E5: GREADER | F5: 0 | G5: 2860.9 | H5: 2865.3 | I5: =H5-G5 -> 4.4 | J5: MAINTENANCE JALAN
B6: 5 | C6: 46264 | D6: A. JUMRIN | E6: XCMG | F6: 35 | G6: 1069.2 | H6: 1077.3 | I6: =H6-G6 -> 8.1 | J6: JETTY AMI
B7: 6 | C7: 46264 | D7: RONAL | E7: LOADER | F7: 150 | G7: 17464.7 | H7: 17470 | I7: =H7-G7 -> 5.3 | J7: ISI TIMBUNAN
B8: 7 | C8: 46264 | D8: AKBAR | E8: BOMAG | F8: 0 | G8: 2445 | H8: 2449 | I8: =H8-G8 -> 4 | J8: MAINTENANCE
B9: 8 | C9: 46266 | D9: RONAL | E9: LOADER | F9: 0 | G9: 17470 | H9: 17472.6 | I9: =H9-G9 -> 2.6 | J9: MAINTENANCE JALAN
B10: 9 | C10: 46266 | D10: DEDI | E10: GREADER | F10: 0 | G10: 2865.3 | H10: 2872.3 | I10: =H10-G10 -> 7 | J10: MAINTENANCE JALAN
B11: 10 | C11: 46266 | D11: A. JUMRIN | E11: XCMG | F11: 0 | G11: 1086.1 | H11: 1091.2 | I11: =H11-G11 -> 5.1 | J11: STEL RAMDOR PPK
B12: 11 | C12: 46266 | D12: AKBAR | E12: BOMAG | F12: 0 | G12: 2449 | H12: 2455 | I12: =H12-G12 -> 6 | J12: BARGING PPK
B13: 12 | C13: 46267 | D13: RONAL | E13: LOADER | F13: 150 | G13: 17474.9 | H13: 17483 | I13: =H13-G13 -> 8.1 | J13: MAINTENANCE DEPAN RAMDOR
... B33: 33 | C33: 46275 | D33: DEDI | E33: GREADER | F33: 0 | G33: 2915.6 | H33: 2922.2 | I33: =H33-G33 -> 6.6 | J33: MAINTENANCE JALAN
B34: 34 | C34: 46276 | D34: RONAL | E34: LOADER | G34: 17510.1 | H34: 17513.4 | I34: =H34-G34 -> 3.3 | J34: BONGKAR MUATAN TONGKANG
B35: 35 | C35: 46276 | D35: AKBAR | E35: BOMAG | G35: 2490 | H35: 2493 | I35: =H35-G35 -> 3 | J35: MAINTENANCE JALAN
B36: 36 | C36: 46276 | D36: A. JUMRIN | E36: XCMG | G36: 1145.7 | H36: 1156.7 | I36: =H36-G36 -> 11 | J36: BONGKAR MUATAN TONGKANG
B37: 37 | C37: 46277 | D37: A. JUMRIN | E37: XCMG | G37: 1156.7 | H37: 1164.7 | I37: =H37-G37 -> 8 | J37: LIPAT TUMPUKAN ORE
B38: 38 | C38: 46277 | D38: RONAL | E38: LOADER | G38: 17513.4 | H38: 17516 | I38: =H38-G38 -> 2.6 | J38: ATUR TUMPUKAN ORE
B39: 39 | C39: 46279 | D39: RONAL | E39: LOADER | G39: 17516 | H39: 17518.8 | I39: =H39-G39 -> 2.8 | J39: BUAT SAFETY BOOM
B40: 40
B41: 41
B42: 42
B46: 40
B47: 41
B48: 42 | F48: =SUM(F2:F47) -> 1410

Sheet REKAP
A1: REKAP OTOMATIS — RINGKASAN UNTUK LAPORAN KE ATASAN
B6: RINGKASAN BBM & BIAYA
B7: Total BBM Masuk (Liter) | C7: =BBM!H685 -> 87340
B8: Total BBM Keluar (Liter) | C8: =BBM!G685 -> 86649
B9: Sisa Stok BBM (Liter) | C9: =MASTER!C7+BBM!H685-BBM!G685 -> 691
B10: Total Biaya BBM Terpakai (Rp) | C10: =BBM!K685 -> 1560043200
B11: Fuel Ratio Rata-rata (Ltr/HM) | C11: =IFERROR(BBM!G685/#REF!,"")
